Workbook
Name A_bboard: [1]Variable!$H$9
Name A_board: [1]Variable!$G$9
Name A_bolt: [1]Variable!$L$4
Name A_stud: [1]Variable!$F$9
Name axial_allow: [1]Variable!$L$41
Name B_board: [1]Variable!$G$5
Name beta: [1]Variable!$L$36
Name buck_inplane: [1]Variable!$L$28
Name buck_torsion: [1]Variable!$L$40
Name buck_weak: [1]Variable!$L$34
Name cmBoard1: [1]Variable!$A$20
Name cmBoard2: [1]Variable!$A$21
Name cmBoard3: [1]Variable!$A$22
Name comp: [1]Variable!$L$10
Name couBOARD: [1]Variable!$C$12
Name Cw_stud: [1]Variable!$F$23
Name Db_comp: [1]Variable!$I$12
Name diaBOLT: [1]Variable!$C$12
Name Ds_comp: [1]Variable!$I$11
Name E_board: [1]Variable!$G$19
Name E_stud: [1]Variable!$F$19
Name Fy_bboard: [1]Variable!$H$18
Name Fy_board: [1]Variable!$G$18
Name Fy_bolt: [1]Variable!$L$3
Name Fy_stud: [1]Variable!$F$18
Name G_stud: [1]Variable!$F$20
Name H_board: [1]Variable!$G$4
Name H_stud: [1]Variable!$F$4
Name Ie_comp: [1]Variable!$L$11
Name Itr: [1]Variable!$I$13
Name Ix_stud: [1]Variable!$F$13
Name Iy_stud: [1]Variable!$F$14
Name J_stud: [1]Variable!$F$22
Name limDeflection: [1]Variable!$C$3
Name limLoad: [1]Variable!$C$4
Name LwithDeflection: [1]Variable!$F$30
Name LwithStress: [1]Variable!$F$29
Name moment_allow: [1]Variable!$I$33
Name moment_bboard: [1]Variable!$I$28
Name moment_board: [1]Variable!$I$27
Name moment_laterbuck: [1]Variable!$I$32
Name moment_stud: [1]Variable!$I$29
Name moment_yield: [1]Variable!$I$30
Name n_comp: [1]Variable!$I$20
Name p: [1]Variable!$F$26
Name ramda: [1]Variable!$L$27
Name Ro_stud: [1]Variable!$F$17
Name Rx_stud: [1]Variable!$F$15
Name Ry_stud: [1]Variable!$F$16
Name S_stud: [1]Variable!$F$8
Name sigma_ex: [1]Variable!$L$30
Name sigma_ey: [1]Variable!$L$31
Name sigma_t: [1]Variable!$L$37
Name spcBOLT: [1]Variable!$C$9
Name spcLAT: [1]Variable!$C$18
Name spcSTUD: [1]Variable!$C$7
Name STUD_C_STUD: "단면성능!$B$42:$B$65"
Name STUD_CH_STUD: "단면성능!$B$16:$B$21"
Name STUD_CH_STUD_improved: "단면성능!$B$22:$B$27"
Name STUD_HR_STUD: "단면성능!$B$6:$B$9"

Sheet VAR.
Q1: {=_xlfn._xlws.FILTER(단면성능!$B$6:$B$69,단면성능!$O$6:$O$69=$A$5,"")}
A2: 기본하중 | B2: 하중(kg/m2) | C2: 24 | F2: 구분 | G2: 석고보드(후면) | J2: 스터드 | K2: 석고보드(전면) | N2: 합성단면
B3: Mu(kN-m) | C3: =MAX(C46:C48) -> 1.5982947 | D3: 보정률 | G3: 3 | H3: 2 | I3: 1 | K3: 1 | L3: 2 | M3: 3
A4: 스터드 타입 | B4: =단면성능!A42 -> C-STUD | C4: =IF($A$5=B4,TRUE,FALSE) -> FALSE | D4: 1 | F4: 종류 | G4: ---- | H4: 방화 | I4: 방화 | J4: 50S-45-08 | K4: 방화 | L4: 방화 | M4: ----
A5: C-STUD(맞댐) | B5: =단면성능!A16 -> CH-STUD | C5: =IF($A$5=B5,TRUE,FALSE) -> FALSE | D5: 1 | F5: 높이(mm) | G5: 0 | H5: 19 | I5: 19 | J5: =IF(C13=TRUE,2,1)*VLOOKUP(J4,단면성능!$B$6:$N$69,2,FALSE)+IF(C13=TRUE, 25,0) -> 50 | K5: 19 | L5: 19 | M5: 0 | N5: =IF(OR(C5=TRUE,C6=TRUE),1+SUM(J5:M5),SUM(G5:M5)) -> 126
B6: =단면성능!A22 -> CH-STUD(개량형) | C6: =IF($A$5=B6,TRUE,FALSE) -> FALSE | D6: 1 | F6: 폭(mm) | G6: =M6 -> 450 | H6: =G6 -> 450 | I6: =H6 -> 450 | J6: =VLOOKUP(J4,단면성능!$B$6:$N$69,3,FALSE)*IF(C12=TRUE,2,1) -> 90 | K6: =C19 -> 450 | L6: =K6 -> 450 | M6: =L6 -> 450 | N6: -
B7: =단면성능!A10 -> T.silent-STUD | C7: =IF($A$5=B7,TRUE,FALSE) -> FALSE | D7: 1 | F7: 유효폭 | G7: =IFERROR(G35*G6,0) -> 0 | H7: =IFERROR(H35*H6,0) -> 6.1307143 | I7: =IFERROR(I35*I6,0) -> 6.1307143 | J7: - | K7: =K35*K6 -> 6.1307143 | L7: =L35*L6 -> 6.1307143 | M7: =IFERROR(M35*M6,0) -> 0 | N7: -
B8: =단면성능!A66 -> R-STUD | C8: =IF($A$5=B8,TRUE,FALSE) -> FALSE | D8: 1 | F8: 두께 | G8: - | H8: - | I8: - | J8: =VLOOKUP(J4,단면성능!$B$6:$N$69,4,FALSE) -> 0.8 | K8: - | L8: - | M8: - | N8: -
B9: =단면성능!A28 -> I-STUD | C9: =IF($A$5=B9,TRUE,FALSE) -> FALSE | D9: 1 | F9: 리브 | G9: - | H9: - | I9: - | J9: =VLOOKUP(SUBSTITUTE(VAR.!J4,"S-","S"),Property_Stud!B:F,4,) -> 10 | K9: - | L9: - | M9: - | N9: -
B10: =단면성능!A6 -> HR-STUD | C10: =IF($A$5=B10,TRUE,FALSE) -> FALSE | D10: 1 | F10: 환산단면적 | G10: =VAR.!G7*VAR.!G5 -> 0 | H10: =VAR.!H7*VAR.!H5 -> 116.48357 | I10: =VAR.!I7*VAR.!I5 -> 116.48357 | J10: =IF(OR(C12=TRUE,C13=TRUE),2,1)*VLOOKUP(J4,단면성능!$B$6:$N$69,5,FALSE) -> 264.32 | K10: =VAR.!K7*VAR.!K5 -> 116.48357 | L10: =VAR.!L7*VAR.!L5 -> 116.48357 | M10: =VAR.!M7*VAR.!M5 -> 0 | N10: =SUM(G10:M10) -> 730.25429
B11: =단면성능!A41 -> RV-STUD | C11: =IF($A$5=B11,TRUE,FALSE) -> FALSE | D11: 1 | F11: 비중(kg/m3) | G11: =IFERROR(G12*100/(G6*10^-3*G5*10^-3),0) -> 0 | H11: =IFERROR(H12*100/(H6*10^-3*H5*10^-3),0) -> 831.26842 | I11: =IFERROR(I12*100/(I6*10^-3*I5*10^-3),0) -> 831.26842 | J11: 76.5 | K11: =K12*100/(K6*10^-3*K5*10^-3) -> 831.26842 | L11: =L12*100/(L6*10^-3*L5*10^-3) -> 831.26842 | M11: =IFERROR(M12*100/(M6*10^-3*M5*10^-3),0) -> 0
B12: C-STUD(맞댐) | C12: =IF($A$5=B12,TRUE,FALSE) -> TRUE | D12: 1 | F12: 단위중량(kN/m) | G12: =IFERROR(VLOOKUP(G4,Property_Gymsumboard!$R$23:$W$32,MATCH(VAR.!G5,Property_Gymsumboard!$S$23:$W$23,0)+1,)*9.81*G6*10^-6,0) -> 0 | H12: =IFERROR(VLOOKUP(H4,Property_Gymsumboard!$R$23:$W$32,MATCH(VAR.!H5,Property_Gymsumboard!$S$23:$W$23,0)+1,)*9.81*H6*10^-6,0) -> 0.07107345 | I12: =IFERROR(VLOOKUP(I4,Property_Gymsumboard!$R$23:$W$32,MATCH(VAR.!I5,Property_Gymsumboard!$S$23:$W$23,0)+1,)*9.81*I6*10^-6,0) -> 0.07107345 | J12: =J10*J11*10^-6 -> 0.02022048 | K12: =VLOOKUP(K4,Property_Gymsumboard!$R$23:$W$32,MATCH(VAR.!K5,Property_Gymsumboard!$S$23:$W$23,0)+1,)*9.81*K6*10^-6 -> 0.07107345 | L12: =VLOOKUP(L4,Property_Gymsumboard!$R$23:$W$32,MATCH(VAR.!L5,Property_Gymsumboard!$S$23:$W$23,0)+1,)*9.81*L6*10^-6 -> 0.07107345 | M12: =IFERROR(VLOOKUP(M4,Property_Gymsumboard!$R$23:$W$32,MATCH(VAR.!M5,Property_Gymsumboard!$S$23:$W$23,0)+1,)*9.81*M6*10^-6,0) -> 0 | N12: =SUM(J12:M12) -> 0.16236738
B13: C-STUD(중앙부연결) | C13: =IF($A$5=B13,TRUE,FALSE) -> FALSE | D13: 0.45 | F13: 총중량(kN) | G13: =G12*$C$20*10^-3 -> 0 | H13: =H12*$C$20*10^-3 -> 0.53305088 | I13: =I12*$C$20*10^-3 -> 0.53305088 | J13: =J12*$C$20*10^-3 -> 0.1516536 | K13: =K12*$C$20*10^-3 -> 0.53305088 | L13: =L12*$C$20*10^-3 -> 0.53305088 | M13: =M12*$C$20*10^-3 -> 0 | N13: =SUM(G13:M13) -> 2.2838571
C14: =IF($A$5=B14,TRUE,FALSE) -> FALSE | D14: 1 | F14: 하단에서의 중립축거리 | G14: =G5/2 -> 0 | H14: =G5+H5/2 -> 9.5 | I14: =SUM($G$5:H5)+I5/2 -> 28.5 | J14: =IF(C13=TRUE,2*VLOOKUP(J4,단면성능!B6:H69,7,)+SUM($G$5:I5),IF(OR(C5=TRUE, C6=TRUE), 1, IF(C8=TRUE, 12.5,0)+SUM($G$5:I5))+VLOOKUP(J4,단면성능!B6:H69,7,)) -> 63 | K14: =IF(OR(C5=TRUE, C6=TRUE), 1, IF(C8=TRUE, 25,0)+SUM($G$5:I5))+J5+K5/2 -> 97.5 | L14: =IF(OR(C5=TRUE, C6=TRUE), 1, IF(C8=TRUE, 25,0)+SUM($G$5:K5))+L5/2 -> 116.5 | M14: =IF(OR(C5=TRUE, C6=TRUE), 1, IF(C8=TRUE, 25,0)+SUM($G$5:L5))+M5/2 -> 126 | N14: -
C15: =IF($A$5=B15,TRUE,FALSE) -> FALSE | D15: 1 | F15: 중립축높이(mm) | G15: 단면적 x 중립축 거리 | N15: =SUM(G16:M16)/VAR.!N10 -> 63
B16: =단면성능!A35 -> MP-STUD | C16: =IF($A$5=B16,TRUE,FALSE) -> FALSE | D16: 1 | G16: =G10*G14 -> 0 | H16: =H10*H14 -> 1106.5939 | I16: =I10*I14 -> 3319.7818 | J16: =J10*J14 -> 16652.16 | K16: =K10*K14 -> 11357.148 | L16: =L10*L14 -> 13570.336 | M16: =M10*M14 -> 0
F17: 중립축이동거리(mm) | G17: =G14-$N$15 -> -63 | H17: =H14-$N$15 -> -53.5 | I17: =I14-$N$15 -> -34.5 | J17: =J14-$N$15 -> 0 | K17: =K14-$N$15 -> 34.5 | L17: =L14-$N$15 -> 53.5 | M17: =M14-$N$15 -> 63 | N17: -
A18: 제한조건 | B18: 처짐제한(1/L) | C18: 240 | F18: 단면2차모멘트 | G18: =1/12*VAR.!G7*VAR.!G5^3 -> 0 | H18: =1/12*VAR.!H7*VAR.!H5^3 -> 3504.2141 | I18: =1/12*VAR.!I7*VAR.!I5^3 -> 3504.2141 | J18: =VLOOKUP(J4,단면성능!$B$6:$N$69,8,FALSE)*IF(C12=TRUE,2,1) -> 116980 | K18: =1/12*VAR.!K7*VAR.!K5^3 -> 3504.2141 | L18: =1/12*VAR.!L7*VAR.!L5^3 -> 3504.2141 | M18: =1/12*VAR.!M7*VAR.!M5^3 -> 0 | N18: - | O18: 개별
B19: 간격(mm) | C19: 450 | G19: =VAR.!G10*(VAR.!G14-VAR.!$N$15)^2+VAR.!G18 -> 0 | H19: =VAR.!H10*(VAR.!H14-VAR.!$N$15)^2+VAR.!H18 -> 336909.32 | I19: =VAR.!I10*(VAR.!I14-VAR.!$N$15)^2+VAR.!I18 -> 142148.79 | J19: =VAR.!J10*(VAR.!J14-VAR.!$N$15)^2+VAR.!J18 -> 116980 | K19: =VAR.!K10*(VAR.!K14-VAR.!$N$15)^2+VAR.!K18 -> 142148.78 | L19: =VAR.!L10*(VAR.!L14-VAR.!$N$15)^2+VAR.!L18 -> 336909.32 | M19: =VAR.!M10*(VAR.!M14-VAR.!$N$15)^2+VAR.!M18 -> 0 | N19: =SUM(G19:M19) -> 1075096.2 | O19: 중립축이동
B20: 지지길이(mm) | C20: 7500 | F20: 축파괴강도(kN) | G20: =IFERROR(G32*G6*G5*10^-3,0) -> 0 | H20: =IFERROR(H32*H6*H5*10^-3,0) -> 68.305263 | I20: =IFERROR(I32*I6*I5*10^-3,0) -> 68.305263 | J20: =J10*J32*10^-3 -> 72.688 | K20: =IFERROR(K32*K6*K5*10^-3,0) -> 68.305263 | L20: =IFERROR(L32*L6*L5*10^-3,0) -> 68.305263 | M20: =IFERROR(M32*M6*M5*10^-3,0) -> 0
B21: ΩMu / Mn | C21: =C3/N36*1.67 -> 0.35763083 | F21: 연결볼트 개수 | G21: 2 | H21: =IF(H4="----",0,IF(G4="----",2,3)) -> 2 | I21: 1 | K21: 1 | L21: 2 | M21: 2
B22: Deflection | C22: =5*(C2*C19*9.81*10^-6)*C20^4/(384*J34*S26) -> 30.584993 | F22: 연결면 전단(볼트) | G22: =$C$31*G21 -> 1884.2016 | H22: =$C$31*H21 -> 1884.2016 | I22: =$C$31*I21 -> 942.1008 | K22: =$C$31*K21 -> 942.1008 | L22: =$C$31*L21 -> 1884.2016 | M22: =$C$31*M21 -> 1884.2016
B23: 1/L | C23: =C20/C18 -> 31.25 | F23: 연결면 지압(N) | G23: =2*0.85*G5*G21*$C$27*G33 -> 0 | H23: =2*0.85*H5*H21*$C$27*H33 -> 3391.5 | I23: =2*0.85*I5*I21*$C$27*I33 -> 1695.75 | J23: =2*0.85*J8*K21*$C$27*J33 -> 1951.6 | K23: =2*0.85*K5*K21*$C$27*K33 -> 1695.75 | L23: =2*0.85*L5*L21*$C$27*L33 -> 3391.5 | M23: =2*0.85*M5*M21*$C$27*M33 -> 0
B24: 처짐 | C24: =IF(C22>C23,"N.G","O.K") -> O.K | F24: 연결면 전단강도(kN) | G24: =MIN(G22,G23)*($C$20/2)/$C$34*10^-3 -> 0 | H24: =MIN(H22,H23)*($C$20/2)/$C$33*10^-3 -> 23.55252 | I24: =MIN(I22,I23)*($C$20/2)/$C$32*10^-3 -> 5.88813 | K24: =MIN(K22,K23)*($C$20/2)/$C$32*10^-3 -> 5.88813 | L24: =MIN(L22,L23)*($C$20/2)/$C$33*10^-3 -> 23.55252 | M24: =MIN(M22,M23)*($C$20/2)/$C$34*10^-3 -> 0
B25: 응력 | C25: =IF(C21>1,"N.G","O.K") -> O.K | F25: 연결면 전단강도 총합 | G25: =MIN(G20,G24) -> 0 | H25: =G25+MIN(H20,G24+H24) -> 23.55252 | I25: =H25+MIN(I20,G24+H24+I24) -> 52.99317 | K25: =L25+MIN(K20,M24+L24+K24) -> 52.99317 | L25: =M25+MIN(L20,M24+L24) -> 23.55252 | M25: =MIN(M20,M24) -> 0 | R25: 보정률 | S25: 보정된 유효단면2차모멘트
F26: 합성률(η) | G26: =G25/MIN(G20,H20+$I$20) -> #DIV/0! | H26: =H25/MIN(H20,I20+$J$20) -> 0.34481267 | I26: =IF(OR(C5=TRUE,C6=TRUE),1,I25/$J$20) -> 0.72904978 | K26: =IF(OR(C5=TRUE,C6=TRUE),1,K25/$J$20) -> 0.72904978 | L26: =L25/MIN(L20,K20+$J$20) -> 0.34481267 | M26: =G25/MIN(G20,H20+$I$20) -> #DIV/0! | N26: =_xlfn.MINIFS(G26:M26,G26:M26, ">0") -> 0.34481267 | R26: 1 | S26: =N27*R26 -> 679593.04
A27: 볼트 | B27: 볼트지름 | C27: 3.5 | F27: 유효단면2차모멘트 | G27: - | H27: - | I27: - | J27: - | K27: - | L27: - | M27: - | N27: =J19+SQRT(N26)*(N19-J19) -> 679593.04 | O27: 합성률 고려
B28: 볼트파단강도 | C28: 480 | F28: 단면계수(상단) | J28: =J19/J5*2 -> 4679.2 | N28: -
B29: 볼트항복강도 | C29: =C28*0.85 -> 408 | F29: 단면계수(하단) | J29: =J19/-J5*2 -> -4679.2 | N29: -
B30: 볼트전단강도 | C30: =C29*0.6 -> 244.8
B31: 볼트강도(개당,N) | C31: =0.5*C30*PI()/4*C27^2 / 1.25 -> 942.1008 | F31: 공칭 휨강도 산정
B32: 볼트간격(1P) | C32: 600 | D32: 1 | F32: 항복강도(Fy) | G32: =IFERROR(VLOOKUP(G4,Property_Gymsumboard!$K$47:$P$56,MATCH(VAR.!G5,Property_Gymsumboard!$S$23:$W$23,0)+1,),0) -> 0 | H32: =VLOOKUP(H4,Property_Gymsumboard!$K$47:$P$56,MATCH(VAR.!H5,Property_Gymsumboard!$S$23:$W$23,0)+1,) -> 7.9889197 | I32: =VLOOKUP(I4,Property_Gymsumboard!$K$47:$P$56,MATCH(VAR.!I5,Property_Gymsumboard!$S$23:$W$23,0)+1,) -> 7.9889197 | J32: 275 | K32: =VLOOKUP(K4,Property_Gymsumboard!$K$47:$P$56,MATCH(VAR.!K5,Property_Gymsumboard!$S$23:$W$23,0)+1,) -> 7.9889197 | L32: =VLOOKUP(L4,Property_Gymsumboard!$K$47:$P$56,MATCH(VAR.!L5,Property_Gymsumboard!$S$23:$W$23,0)+1,) -> 7.9889197 | M32: =VLOOKUP(M4,Property_Gymsumboard!$K$47:$P$56,MATCH(VAR.!M5,Property_Gymsumboard!$S$23:$W$23,0)+1,) -> #N/A
B33: 볼트간격(2P) | C33: 300 | D33: 2 | F33: 인장강도(Fu) | G33: 15 | H33: 15 | I33: 15 | J33: 410 | K33: 15 | L33: 15 | M33: 15
B34: 볼트간격(3P) | C34: 300 | D34: 2 | F34: 탄성계수(E) | G34: =VLOOKUP(G4,Property_Gymsumboard!$Y$23:$AD$32,MATCH(VAR.!G5,Property_Gymsumboard!$S$23:$W$23,0)+1,)*10^3 -> #N/A | H34: =VLOOKUP(H4,Property_Gymsumboard!$Y$23:$AD$32,MATCH(VAR.!H5,Property_Gymsumboard!$S$23:$W$23,0)+1,)*10^3 -> 2861 | I34: =VLOOKUP(I4,Property_Gymsumboard!$Y$23:$AD$32,MATCH(VAR.!I5,Property_Gymsumboard!$S$23:$W$23,0)+1,)*10^3 -> 2861 | J34: 210000 | K34: =VLOOKUP(K4,Property_Gymsumboard!$Y$23:$AD$32,MATCH(VAR.!K5,Property_Gymsumboard!$S$23:$W$23,0)+1,)*10^3 -> 2861 | L34: =VLOOKUP(L4,Property_Gymsumboard!$Y$23:$AD$32,MATCH(VAR.!L5,Property_Gymsumboard!$S$23:$W$23,0)+1,)*10^3 -> 2861 | M34: =VLOOKUP(M4,Property_Gymsumboard!$Y$23:$AD$32,MATCH(VAR.!M5,Property_Gymsumboard!$S$23:$W$23,0)+1,)*10^3 -> #N/A
F35: 탄성계수비(n) | G35: =VAR.!G34/VAR.!J34 -> #N/A | H35: =VAR.!H34/VAR.!J34 -> 0.01362381 | I35: =VAR.!I34/VAR.!J34 -> 0.01362381 | J35: 1 | K35: =VAR.!K34/VAR.!J34 -> 0.01362381 | L35: =VAR.!L34/VAR.!J34 -> 0.01362381 | M35: =VAR.!M34/VAR.!J34 -> #N/A
A36: 활하중 | B36: 0.24 | C36: =1/8*B36*C19*(C20*10^-3)^2*10^-3 -> 0.759375 | F36: 공칭강도(Mn) | G36: =ABS(MIN(G20,G25)*G17*10^-3) -> 0 | H36: =ABS(MIN(H20,H25)*H17*10^-3) -> 1.2600598 | I36: =ABS(MIN(I20,I25)*I17*10^-3) -> 1.8282644 | J36: =MAX(ABS(J32*VAR.!J28*10^-6),ABS(J32*VAR.!J29*10^-6)) -> 1.28678 | K36: =ABS(MIN(K20,K25)*K17*10^-3) -> 1.8282644 | L36: =ABS(MIN(L20,L25)*L17*10^-3) -> 1.2600598 | M36: =ABS(MIN(M20,M25)*M17*10^-3) -> 0 | N36: =SUM(G36:M36) -> 7.4634284
A37: 지진하중 산정 | B37: 총중량 | C37: =N13 -> 2.2838571
B38: Fa = | C38: 1.3
B39: S = | C39: 0.22
B40: Sds = | C40: =C39*2.5*2/3*C38 -> 0.47666667
...

Sheet Property_Gymsumboard
B1: 강도
C2: 9.5 | D2: 12.5 | E2: 15 | F2: 19 | G2: 25 | I2: 비중
A3: 0 | B3: 일반/방수/방음 | C3: 360 | D3: 500 | E3: 650 | F3: 756 | G3: 1000 | H3: 1000000 | I3: 650 | J3: 1 | K3: ="THK - "&tBoard1 -> THK - 19 | L3: ="THK - "&tBoard2 -> THK - 19 | M3: ="THK - "&tBoard3 -> THK - 100
A4: 1 | B4: 전방수 | C4: 360 | D4: 500 | E4: 650 | F4: 756 | G4: 1000 | H4: 1000000 | I4: 650 | J4: 2 | K4: ="THK - "&tBoard1 -> THK - 19 | L4: ="THK - "&tBoard2 -> THK - 19 | M4: ="THK - "&tBoard3 -> THK - 100
A5: 2 | B5: 방화 또는 방화방수 | C5: 360 | D5: 500 | E5: 650 | F5: 756 | G5: 1000 | H5: 1000000 | I5: 750 | J5: 3 | K5: ="THK - "&tBoard1 -> THK - 19 | L5: ="THK - "&tBoard2 -> THK - 19 | M5: ="THK - "&tBoard3 -> THK - 100
A6: 3 | B6: 고강도 | C6: 500 | D6: 700 | E6: 910 | F6: 1 | G6: 1 | H6: 1000000 | I6: 850 | J6: 4 | K6: ="THK - "&tBoard1 -> THK - 19 | L6: ="THK - "&tBoard2 -> THK - 19 | M6: ="THK - "&tBoard3 -> THK - 100
A7: 4 | B7: ---- | C7: 1000000 | D7: 1000000 | E7: 1000000 | F7: 1000000 | G7: 1000000 | H7: 1000000 | I7: 0 | J7: 0
B9: 9.5 | C9: 2
B10: 12.5 | C10: 3
B11: 15 | C11: 4
B12: 19 | C12: 5
B13: 25 | C13: 6
B14: 1e-29 | C14: 7
A16: 탄성계수 | C16: 9.5 | D16: 12.5 | E16: 15 | F16: 19 | G16: 25
A17: 0 | B17: 일반/방수/방음 | C17: 3.2 | D17: 2.7 | E17: 2.6 | F17: 1.9 | G17: 1.9 | H17: 0
A18: 1 | B18: 전방수 | C18: 1.9 | D18: 5.3 | E18: 2.1 | F18: 1.9 | G18: 1.9 | H18: 0
A19: 2 | B19: 방화 또는 방화방수 | C19: 1.9 | D19: 3.5 | E19: 4.2 | F19: 3 | G19: 2.5 | H19: 0
A20: 3 | B20: 고강도 | C20: 1.9 | D20: 4 | E20: 1.9 | F20: 1.9 | G20: 1.9 | H20: 1000000
A21: 4 | B21: ---- | C21: 0 | D21: 0 | E21: 0 | F21: 0 | G21: 0 | H21: 0
K22: 파괴강도 | R22: 질량 | S22: kg/m2 | Y22: 탄성계수
C23: 9.5 | D23: 12.5 | E23: 15 | F23: 19 | G23: 25 | L23: 9.5 | M23: 12.5 | N23: 15 | O23: 19 | P23: 25 | S23: 9.5 | T23: 12.5 | U23: 15 | V23: 19 | W23: 25 | Z23: 9.5 | AA23: 12.5 | AB23: 15 | AC23: 19 | AD23: 25
B24: 일반 | C24: =C3 -> 360 | D24: =D3 -> 500 | E24: =E3 -> 650 | K24: 일반 | L24: 162 | M24: 210 | N24: 277 | R24: 일반 | S24: 5.4 | T24: 7.1 | U24: 8.4 | Y24: 일반 | Z24: 3.241 | AA24: 2.67 | AB24: 2.581
B25: 방수 | C25: =C24 -> 360 | D25: =D24 -> 500 | K25: 방수 | L25: 303 | M25: 335 | R25: 방수 | S25: 5.4 | T25: 7.1 | Y25: 방수
B26: 방균 | C26: =C24 -> 360 | D26: =D24 -> 500 | K26: 방균 | L26: 150 | M26: 221 | R26: 방균 | S26: 5.4 | T26: 7.1 | Y26: 방균
B27: 방화 | D27: 500 | E27: 650 | F27: 756 | G27: 1000 | K27: 방화 | M27: 274 | N27: 323 | O27: 515 | P27: 906 | R27: 방화 | T27: 10.5 | U27: 13.1 | V27: 16.1 | W27: 21.3 | Y27: 방화 | AA27: 2.992 | AB27: 4.127 | AC27: 2.861 | AD27: 2.275
B28: 방화방수 | D28: =D27 -> 500 | E28: =E27 -> 650 | F28: =F27 -> 756 | K28: 방화방수 | M28: 297 | N28: 411 | O28: 512 | R28: 방화방수 | T28: 10.7 | U28: 13.1 | V28: 15.9 | Y28: 방화방수
B29: 차음 | C29: =C5 -> 360 | D29: =D5 -> 500 | K29: 차음 | L29: 200 | M29: 269 | R29: 차음 | T29: 10.5 | U29: 12.5 | Y29: 차음
B30: 고강도일반 | D30: =D6 -> 700 | E30: =E6 -> 910 | K30: 고강도일반 | M30: 579 | N30: 560 | R30: 고강도일반 | T30: 13.2 | U30: 15.8 | Y30: 고강도일반 | AA30: 3.491
B31: 전방수 | D31: =D4 -> 500 | E31: =E4 -> 650 | K31: 전방수 | M31: 321 | N31: 397 | R31: 전방수 | T31: 10.7 | Y31: 전방수 | AA31: 5.048 | AB31: 2.05
B32: 고강도전방수 | D32: =D30 -> 700 | K32: 고강도전방수 | M32: 412 | R32: 고강도전방수 | T32: 12.6 | Y32: 고강도전방수
B34: ---- | K34: 파괴응력 검토
B35: 일반 | L35: 9.5 | M35: 12.5 | N35: 15 | O35: 19 | P35: 25
B36: 방수 | K36: 일반 | L36: =L24*0.35/(0.3*((L$35/2)*10^-3)^2)*1.5*10^-6 -> 12.565097 | M36: =M24*0.35/(0.3*((M$35/2)*10^-3)^2)*1.5*10^-6 -> 9.408 | N36: =N24*0.35/(0.3*((N$35/2)*10^-3)^2)*1.5*10^-6 -> 8.6177778
B37: 방균 | K37: 방수 | L37: =L25*0.35/(0.3*((L$35/2)*10^-3)^2)*1.5*10^-6 -> 23.501385 | M37: =M25*0.35/(0.3*((M$35/2)*10^-3)^2)*1.5*10^-6 -> 15.008
B38: 방화 | K38: 방균 | L38: =L26*0.35/(0.3*((L$35/2)*10^-3)^2)*1.5*10^-6 -> 11.634349 | M38: =M26*0.35/(0.3*((M$35/2)*10^-3)^2)*1.5*10^-6 -> 9.9008
B39: 방화방수 | K39: 방화 | M39: =M27*0.35/(0.3*((M$35/2)*10^-3)^2)*1.5*10^-6 -> 12.2752 | N39: =N27*0.35/(0.3*((N$35/2)*10^-3)^2)*1.5*10^-6 -> 10.048889 | O39: =O27*0.35/(0.3*((O$35/2)*10^-3)^2)*1.5*10^-6 -> 9.9861496 | P39: =P27*0.35/(0.3*((P$35/2)*10^-3)^2)*1.5*10^-6 -> 10.1472
B40: 차음 | K40: 방화방수 | M40: =M28*0.35/(0.3*((M$35/2)*10^-3)^2)*1.5*10^-6 -> 13.3056 | N40: =N28*0.35/(0.3*((N$35/2)*10^-3)^2)*1.5*10^-6 -> 12.786667 | O40: =O28*0.35/(0.3*((O$35/2)*10^-3)^2)*1.5*10^-6 -> 9.9279778
B41: 고강도일반 | K41: 차음 | L41: =L29*0.35/(0.3*((L$35/2)*10^-3)^2)*1.5*10^-6 -> 15.512465 | M41: =M29*0.35/(0.3*((M$35/2)*10^-3)^2)*1.5*10^-6 -> 12.0512
B42: 전방수 | K42: 고강도일반 | M42: =M30*0.35/(0.3*((M$35/2)*10^-3)^2)*1.5*10^-6 -> 25.9392 | N42: =N30*0.35/(0.3*((N$35/2)*10^-3)^2)*1.5*10^-6 -> 17.422222
B43: 고강도전방수 | K43: 전방수 | M43: =M31*0.35/(0.3*((M$35/2)*10^-3)^2)*1.5*10^-6 -> 14.3808 | N43: =N31*0.35/(0.3*((N$35/2)*10^-3)^2)*1.5*10^-6 -> 12.351111
...

Sheet SCREWBOLT 
T1: 6061-T6 | U1: 290
B2: 2Øu·Ftu1·D·T1 = | D2: ="2 X 0.85 X "&#REF!&" X "&#REF!& " X "&#REF!&" =" -> #REF! | T2: 6063-T5 | U2: 145
B3: 2Øu·Ftu2·D·T2 = | D3: ="2 X 0.85 X "&#REF!&" X "&#REF!& " X "&#REF!&" =" -> #REF! | T3: 6063-T6 | U3: 205
B4: 4.2(T23·D)1/2Øsc·Ftu2 = | D4: ="4.2 X √( "&#REF!^3&" X "&#REF!& ") X 0.5 X "&#REF!&" =" -> #REF! | T4: STS304 | U4: 520
B5: Øsc·Pns / 1.25 = | D5: ="0.5 X "&ROUNDUP(#REF!*#REF!,2)&" / 1.25 = " -> #REF! | T5: STS316 | U5: 520
T6: SS400 | U6: 400
T7: SM490 | U7: 490
T8: 2024-T4 | U8: 425
T9: 7075-T73 | U9: 470

Sheet Property_Stud
C1: 폭(b) | D1: 높이(h) | E1: 립높이(a) | F1: 두께(t) | G1: 단면적 | H1: 단위중량 | I1: Ixx | J1: Rx | K1: Iyy | L1: Ry | M1: Ycg | N1: Xcg | O1: 전단중심 | P1: 비틀림상수 | Q1: 뒤틀림상수 | R1: Iyy | S1: 비틀림상수 | T1: 뒤틀림상수 | U1: Ry
A2: C-STUD | B2: 50S45-08 | C2: 45 | D2: 50 | E2: 10 | F2: 0.8 | G2: 138.5 | H2: 1.02 | I2: 56000 | J2: =SQRT(I2/G2) -> 20.108012 | K2: 39000 | L2: =SQRT(K2/G2) -> 16.780597 | M2: 25 | N2: =( D2 * F2^2 / 2 + 2 * F2 * C2^2 /2 + 2 * F2*E2 *C2)/G2 -> 17.01083 | O2: =(3*C2*D2^2*(C2+2*E2)-8*C2*E2^3)/(D2^2*(D2+6*C2+6*E2)+4*E2^2*(2*E2-3*D2))+N2 -> 41.039227 | P2: =(F2^3*D2 + 2*F2^3*C2 + 2*F2^3*E2)/3 -> 27.306667 | Q2: =((C2^3*D2^2*F2)/12)*((2*D2*F2+3*C2*F2)/(D2*F2+6*F2*C2)) -> 11153320 | R2: =2*(K2+G2*N2^2) -> 158155.03 | S2: =((2*F2)^3*D2 + 2*F2^3*(2*C2) + 4*F2^3*E2)/3 -> 105.81333 | T2: =D2^2/4 * (2*R2) -> 1.9769379e+08 | U2: =SQRT(R2/(2*G2)) -> 23.894702
B3: 50S45-10 | C3: 45 | D3: 50 | E3: 10 | F3: 1 | G3: 161 | H3: 1.26 | I3: 69000 | J3: =SQRT(I3/G3) -> 20.701967 | K3: 48000 | L3: =SQRT(K3/G3) -> 17.266634 | M3: 25 | N3: =( D3 * F3^2 / 2 + 2 * F3 * C3^2 /2 + 2 * F3*E3 *C3)/G3 -> 18.322981 | O3: =(3*C3*D3^2*(C3+2*E3)-8*C3*E3^3)/(D3^2*(D3+6*C3+6*E3)+4*E3^2*(2*E3-3*D3))+N3 -> 42.351378 | P3: =(F3^3*D3 + 2*F3^3*C3 + 2*F3^3*E3)/3 -> 53.333333 | Q3: =((C3^3*D3^2*F3)/12)*((2*D3*F3+3*C3*F3)/(D3*F3+6*F3*C3)) -> 13941650 | R3: =2*(K3+G3*N3^2) -> 204105.59 | S3: =((2*F3)^3*D3 + 2*F3^3*(2*C3) + 4*F3^3*E3)/3 -> 206.66667 | T3: =D3^2/4 * (2*R3) -> 2.5513199e+08 | U3: =SQRT(R3/(2*G3)) -> 25.176741
B4: 65S45-08 | C4: 45 | D4: 65 | E4: 10 | F4: 0.8 | G4: 142 | H4: 1.11 | I4: 101000 | J4: =SQRT(I4/G4) -> 26.669601 | K4: 43000 | L4: =SQRT(K4/G4) -> 17.401635 | M4: 32.5 | N4: =( D4 * F4^2 / 2 + 2 * F4 * C4^2 /2 + 2 * F4*E4 *C4)/G4 -> 16.625352 | O4: =(3*C4*D4^2*(C4+2*E4)-8*C4*E4^3)/(D4^2*(D4+6*C4+6*E4)+4*E4^2*(2*E4-3*D4))+N4 -> 39.587982 | P4: =(F4^3*D4 + 2*F4^3*C4 + 2*F4^3*E4)/3 -> 29.866667 | Q4: =((C4^3*D4^2*F4)/12)*((2*D4*F4+3*C4*F4)/(D4*F4+6*F4*C4)) -> 20303647 | R4: =2*(K4+G4*N4^2) -> 164498.26 | S4: =((2*F4)^3*D4 + 2*F4^3*(2*C4) + 4*F4^3*E4)/3 -> 126.29333 | T4: =D4^2/4 * (2*R4) -> 3.4750258e+08 | U4: =SQRT(R4/(2*G4)) -> 24.066974
B5: 65S45-10 | C5: 45 | D5: 65 | E5: 10 | F5: 1 | G5: 176 | H5: 1.38 | I5: 125000 | J5: =SQRT(I5/G5) -> 26.65009 | K5: 53000 | L5: =SQRT(K5/G5) -> 17.353281 | M5: 32.5 | N5: =( D5 * F5^2 / 2 + 2 * F5 * C5^2 /2 + 2 * F5*E5 *C5)/G5 -> 16.803977 | O5: =(3*C5*D5^2*(C5+2*E5)-8*C5*E5^3)/(D5^2*(D5+6*C5+6*E5)+4*E5^2*(2*E5-3*D5))+N5 -> 39.766607 | P5: =(F5^3*D5 + 2*F5^3*C5 + 2*F5^3*E5)/3 -> 58.333333 | Q5: =((C5^3*D5^2*F5)/12)*((2*D5*F5+3*C5*F5)/(D5*F5+6*F5*C5)) -> 25379559 | R5: =2*(K5+G5*N5^2) -> 205395.53 | S5: =((2*F5)^3*D5 + 2*F5^3*(2*C5) + 4*F5^3*E5)/3 -> 246.66667 | T5: =D5^2/4 * (2*R5) -> 4.3389805e+08 | U5: =SQRT(R5/(2*G5)) -> 24.155952
B6: 75S45-08 | C6: 45 | D6: 75 | E6: 10 | F6: 0.8 | G6: 150 | H6: 1.17 | I6: 140000 | J6: =SQRT(I6/G6) -> 30.550505 | K6: 46000 | L6: =SQRT(K6/G6) -> 17.511901 | M6: 37.5 | N6: =( D6 * F6^2 / 2 + 2 * F6 * C6^2 /2 + 2 * F6*E6 *C6)/G6 -> 15.76 | O6: =(3*C6*D6^2*(C6+2*E6)-8*C6*E6^3)/(D6^2*(D6+6*C6+6*E6)+4*E6^2*(2*E6-3*D6))+N6 -> 38.071742 | P6: =(F6^3*D6 + 2*F6^3*C6 + 2*F6^3*E6)/3 -> 31.573333 | Q6: =((C6^3*D6^2*F6)/12)*((2*D6*F6+3*C6*F6)/(D6*F6+6*F6*C6)) -> 28228940 | R6: =2*(K6+G6*N6^2) -> 166513.28 | S6: =((2*F6)^3*D6 + 2*F6^3*(2*C6) + 4*F6^3*E6)/3 -> 139.94667 | T6: =D6^2/4 * (2*R6) -> 468318600 | U6: =SQRT(R6/(2*G6)) -> 23.559377
B7: 75S45-10 | C7: 45 | D7: 75 | E7: 10 | F7: 1 | G7: 186 | H7: 1.46 | I7: 173000 | J7: =SQRT(I7/G7) -> 30.497664 | K7: 56000 | L7: =SQRT(K7/G7) -> 17.351521 | M7: 37.5 | N7: =( D7 * F7^2 / 2 + 2 * F7 * C7^2 /2 + 2 * F7*E7 *C7)/G7 -> 15.927419 | O7: =(3*C7*D7^2*(C7+2*E7)-8*C7*E7^3)/(D7^2*(D7+6*C7+6*E7)+4*E7^2*(2*E7-3*D7))+N7 -> 38.239162 | P7: =(F7^3*D7 + 2*F7^3*C7 + 2*F7^3*E7)/3 -> 61.666667 | Q7: =((C7^3*D7^2*F7)/12)*((2*D7*F7+3*C7*F7)/(D7*F7+6*F7*C7)) -> 35286175 | R7: =2*(K7+G7*N7^2) -> 206369.96 | S7: =((2*F7)^3*D7 + 2*F7^3*(2*C7) + 4*F7^3*E7)/3 -> 273.33333 | T7: =D7^2/4 * (2*R7) -> 5.8041551e+08 | U7: =SQRT(R7/(2*G7)) -> 23.5533
B8: 80S45-08 | C8: 45 | D8: 80 | E8: 10 | F8: 0.8 | G8: 150 | H8: 1.17 | I8: 140000 | J8: =SQRT(I8/G8) -> 30.550505 | K8: 46000 | L8: =SQRT(K8/G8) -> 17.511901 | M8: 37.5 | N8: =( D8 * F8^2 / 2 + 2 * F8 * C8^2 /2 + 2 * F8*E8 *C8)/G8 -> 15.770667 | O8: =(3*C8*D8^2*(C8+2*E8)-8*C8*E8^3)/(D8^2*(D8+6*C8+6*E8)+4*E8^2*(2*E8-3*D8))+N8 -> 37.773821 | P8: =(F8^3*D8 + 2*F8^3*C8 + 2*F8^3*E8)/3 -> 32.426667 | Q8: =((C8^3*D8^2*F8)/12)*((2*D8*F8+3*C8*F8)/(D8*F8+6*F8*C8)) -> 32770286 | R8: =2*(K8+G8*N8^2) -> 166614.18 | S8: =((2*F8)^3*D8 + 2*F8^3*(2*C8) + 4*F8^3*E8)/3 -> 146.77333 | T8: =D8^2/4 * (2*R8) -> 5.3316537e+08 | U8: =SQRT(R8/(2*G8)) -> 23.566514
B9: 80S45-10 | C9: 45 | D9: 80 | E9: 10 | F9: 1 | G9: 186 | H9: 1.46 | I9: 173000 | J9: =SQRT(I9/G9) -> 30.497664 | K9: 56000 | L9: =SQRT(K9/G9) -> 17.351521 | M9: 37.5 | N9: =( D9 * F9^2 / 2 + 2 * F9 * C9^2 /2 + 2 * F9*E9 *C9)/G9 -> 15.94086 | O9: =(3*C9*D9^2*(C9+2*E9)-8*C9*E9^3)/(D9^2*(D9+6*C9+6*E9)+4*E9^2*(2*E9-3*D9))+N9 -> 37.944015 | P9: =(F9^3*D9 + 2*F9^3*C9 + 2*F9^3*E9)/3 -> 63.333333 | Q9: =((C9^3*D9^2*F9)/12)*((2*D9*F9+3*C9*F9)/(D9*F9+6*F9*C9)) -> 40962857 | R9: =2*(K9+G9*N9^2) -> 206529.3 | S9: =((2*F9)^3*D9 + 2*F9^3*(2*C9) + 4*F9^3*E9)/3 -> 286.66667 | T9: =D9^2/4 * (2*R9) -> 6.6089376e+08 | U9: =SQRT(R9/(2*G9)) -> 23.562392
B10: 90S45-08 | C10: 45 | D10: 90 | E10: 10 | F10: 0.8 | G10: 162 | H10: 1.27 | I10: 213000 | J10: =SQRT(I10/G10) -> 36.260375 | K10: 49000 | L10: =SQRT(K10/G10) -> 17.39164 | M10: 45 | N10: =( D10 * F10^2 / 2 + 2 * F10 * C10^2 /2 + 2 * F10*E10 *C10)/G10 -> 14.622222 | O10: =(3*C10*D10^2*(C10+2*E10)-8*C10*E10^3)/(D10^2*(D10+6*C10+6*E10)+4*E10^2*(2*E10-3*D10))+N10 -> 36.038788 | P10: =(F10^3*D10 + 2*F10^3*C10 + 2*F10^3*E10)/3 -> 34.133333 | Q10: =((C10^3*D10^2*F10)/12)*((2*D10*F10+3*C10*F10)/(D10*F10+6*F10*C10)) -> 43056562 | R10: =2*(K10+G10*N10^2) -> 167274.24 | S10: =((2*F10)^3*D10 + 2*F10^3*(2*C10) + 4*F10^3*E10)/3 -> 160.42667 | T10: =D10^2/4 * (2*R10) -> 677460672 | U10: =SQRT(R10/(2*G10)) -> 22.721763
B11: 90S45-10 | C11: 45 | D11: 90 | E11: 10 | F11: 1 | G11: 201 | H11: 1.58 | I11: 264000 | J11: =SQRT(I11/G11) -> 36.241314 | K11: 60000 | L11: =SQRT(K11/G11) -> 17.277369 | M11: 45 | N11: =( D11 * F11^2 / 2 + 2 * F11 * C11^2 /2 + 2 * F11*E11 *C11)/G11 -> 14.776119 | O11: =(3*C11*D11^2*(C11+2*E11)-8*C11*E11^3)/(D11^2*(D11+6*C11+6*E11)+4*E11^2*(2*E11-3*D11))+N11 -> 36.192685 | P11: =(F11^3*D11 + 2*F11^3*C11 + 2*F11^3*E11)/3 -> 66.666667 | Q11: =((C11^3*D11^2*F11)/12)*((2*D11*F11+3*C11*F11)/(D11*F11+6*F11*C11)) -> 53820703 | R11: =2*(K11+G11*N11^2) -> 207770.15 | S11: =((2*F11)^3*D11 + 2*F11^3*(2*C11) + 4*F11^3*E11)/3 -> 313.33333 | T11: =D11^2/4 * (2*R11) -> 8.414691e+08 | U11: =SQRT(R11/(2*G11)) -> 22.734141
B12: 100S45-08 | C12: 45 | D12: 100 | E12: 10 | F12: 0.8 | G12: 170 | H12: 1.3 | I12: 272000 | J12: =SQRT(I12/G12) -> 40 | K12: 51000 | L12: =SQRT(K12/G12) -> 17.320508 | M12: 50 | N12: =( D12 * F12^2 / 2 + 2 * F12 * C12^2 /2 + 2 * F12*E12 *C12)/G12 -> 13.952941 | O12: =(3*C12*D12^2*(C12+2*E12)-8*C12*E12^3)/(D12^2*(D12+6*C12+6*E12)+4*E12^2*(2*E12-3*D12))+N12 -> 34.819703 | P12: =(F12^3*D12 + 2*F12^3*C12 + 2*F12^3*E12)/3 -> 35.84 | Q12: =((C12^3*D12^2*F12)/12)*((2*D12*F12+3*C12*F12)/(D12*F12+6*F12*C12)) -> 55003378 | R12: =2*(K12+G12*N12^2) -> 168192.75 | S12: =((2*F12)^3*D12 + 2*F12^3*(2*C12) + 4*F12^3*E12)/3 -> 174.08 | T12: =D12^2/4 * (2*R12) -> 8.4096376e+08 | U12: =SQRT(R12/(2*G12)) -> 22.241506
B13: 100S45-10 | C13: 45 | D13: 100 | E13: 10 | F13: 1 | G13: 211 | H13: 1.66 | I13: 336000 | J13: =SQRT(I13/G13) -> 39.905101 | K13: 62000 | L13: =SQRT(K13/G13) -> 17.141729 | M13: 50 | N13: =( D13 * F13^2 / 2 + 2 * F13 * C13^2 /2 + 2 * F13*E13 *C13)/G13 -> 14.099526 | O13: =(3*C13*D13^2*(C13+2*E13)-8*C13*E13^3)/(D13^2*(D13+6*C13+6*E13)+4*E13^2*(2*E13-3*D13))+N13 -> 34.966288 | P13: =(F13^3*D13 + 2*F13^3*C13 + 2*F13^3*E13)/3 -> 70 | Q13: =((C13^3*D13^2*F13)/12)*((2*D13*F13+3*C13*F13)/(D13*F13+6*F13*C13)) -> 68754223 | R13: =2*(K13+G13*N13^2) -> 207892.18 | S13: =((2*F13)^3*D13 + 2*F13^3*(2*C13) + 4*F13^3*E13)/3 -> 340 | T13: =D13^2/4 * (2*R13) -> 1.0394609e+09 | U13: =SQRT(R13/(2*G13)) -> 22.195394
B14: 110S45-08 | C14: 45 | D14: 110 | E14: 10 | F14: 0.8 | G14: =(2*E14*F14+D14*F14+2*C14*F14)*0.98 -> 172.48 | H14: =G14*7.82*10^-3 -> 1.3487936 | I14: =(1/12*F14*D14^3+2*C14*F14*(D14/2)^2 + E14*F14*((D14/2-E14/2)^2+(D14-E14/2)^2))*0.744 -> 308561.6 | J14: =SQRT(I14/G14) -> 42.296221 | K14: =D14*F14*(N14-F14/2)^2+2*F14*C14*(N14-C14/2)+2*F14*E14*(C14-N14)^2 -> 30708.297 | L14: =SQRT(K14/G14) -> 13.343154 | M14: =D14/2 -> 55 | N14: =( D14 * F14^2 / 2 + 2 * F14 * C14^2 /2 + 2 * F14*E14 *C14)/G14 -> 13.770872 | O14: =(3*C14*D14^2*(C14+2*E14)-8*C14*E14^3)/(D14^2*(D14+6*C14+6*E14)+4*E14^2*(2*E14-3*D14))+N14 -> 34.120391 | P14: =(F14^3*D14 + 2*F14^3*C14 + 2*F14^3*E14)/3 -> 37.546667 | Q14: =((C14^3*D14^2*F14)/12)*((2*D14*F14+3*C14*F14)/(D14*F14+6*F14*C14)) -> 68671480 | R14: =2*(K14+G14*N14^2) -> 126833.74 | S14: =((2*F14)^3*D14 + 2*F14^3*(2*C14) + 4*F14^3*E14)/3 -> 187.73333 | T14: =D14^2/4 * (2*R14) -> 7.6734415e+08 | U14: =SQRT(R14/(2*G14)) -> 19.174897
B15: 110S45-10 | C15: 45 | D15: 110 | E15: 10 | F15: 1 | G15: =(2*E15*F15+D15*F15+2*C15*F15)*0.98 -> 215.6 | H15: =G15*7.82*10^-3 -> 1.685992 | I15: =(1/12*F15*D15^3+2*C15*F15*(D15/2)^2 + E15*F15*((D15/2-E15/2)^2+(D15-E15/2)^2))*0.744 -> 385702 | J15: =SQRT(I15/G15) -> 42.296221 | K15: =D15*F15*(N15-F15/2)^2+2*F15*C15*(N15-C15/2)+2*F15*E15*(C15-N15)^2 -> 38182.468 | L15: =SQRT(K15/G15) -> 13.307842 | M15: =D15/2 -> 55 | N15: =( D15 * F15^2 / 2 + 2 * F15 * C15^2 /2 + 2 * F15*E15 *C15)/G15 -> 13.821892 | O15: =(3*C15*D15^2*(C15+2*E15)-8*C15*E15^3)/(D15^2*(D15+6*C15+6*E15)+4*E15^2*(2*E15-3*D15))+N15 -> 34.171412 | P15: =(F15^3*D15 + 2*F15^3*C15 + 2*F15^3*E15)/3 -> 73.333333 | Q15: =((C15^3*D15^2*F15)/12)*((2*D15*F15+3*C15*F15)/(D15*F15+6*F15*C15)) -> 85839350 | R15: =2*(K15+G15*N15^2) -> 158743.41 | S15: =((2*F15)^3*D15 + 2*F15^3*(2*C15) + 4*F15^3*E15)/3 -> 366.66667 | T15: =D15^2/4 * (2*R15) -> 9.6039766e+08 | U15: =SQRT(R15/(2*G15)) -> 19.187062
B16: 120S45-08 | C16: 45 | D16: 120 | E16: 10 | F16: 0.8 | G16: =(2*E16*F16+D16*F16+2*C16*F16)*0.98 -> 180.32 | H16: =G16*7.82*10^-3 -> 1.4101024 | I16: =(1/12*F16*D16^3+2*C16*F16*(D16/2)^2 + E16*F16*((D16/2-E16/2)^2+(D16-E16/2)^2))*0.744 -> 375273.6 | J16: =SQRT(I16/G16) -> 45.619661 | K16: =D16*F16*(N16-F16/2)^2+2*F16*C16*(N16-C16/2)+2*F16*E16*(C16-N16)^2 -> 31223.597 | L16: =SQRT(K16/G16) -> 13.158898 | M16: =D16/2 -> 60 | N16: =( D16 * F16^2 / 2 + 2 * F16 * C16^2 /2 + 2 * F16*E16 *C16)/G16 -> 13.189885 | O16: =(3*C16*D16^2*(C16+2*E16)-8*C16*E16^3)/(D16^2*(D16+6*C16+6*E16)+4*E16^2*(2*E16-3*D16))+N16 -> 33.051171 | P16: =(F16^3*D16 + 2*F16^3*C16 + 2*F16^3*E16)/3 -> 39.253333 | Q16: =((C16^3*D16^2*F16)/12)*((2*D16*F16+3*C16*F16)/(D16*F16+6*F16*C16)) -> 84115385 | R16: =2*(K16+G16*N16^2) -> 125188.84 | S16: =((2*F16)^3*D16 + 2*F16^3*(2*C16) + 4*F16^3*E16)/3 -> 201.38667 | T16: =D16^2/4 * (2*R16) -> 9.0135963e+08 | U16: =SQRT(R16/(2*G16)) -> 18.631416
B17: 120S45-10 | C17: 45 | D17: 120 | E17: 10 | F17: 1 | G17: =(2*E17*F17+D17*F17+2*C17*F17)*0.98 -> 225.4 | H17: =G17*7.82*10^-3 -> 1.762628 | I17: =(1/12*F17*D17^3+2*C17*F17*(D17/2)^2 + E17*F17*((D17/2-E17/2)^2+(D17-E17/2)^2))*0.744 -> 469092 | J17: =SQRT(I17/G17) -> 45.619661 | K17: =D17*F17*(N17-F17/2)^2+2*F17*C17*(N17-C17/2)+2*F17*E17*(C17-N17)^2 -> 38823.328 | L17: =SQRT(K17/G17) -> 13.124097 | M17: =D17/2 -> 60 | N17: =( D17 * F17^2 / 2 + 2 * F17 * C17^2 /2 + 2 * F17*E17 *C17)/G17 -> 13.243123 | O17: =(3*C17*D17^2*(C17+2*E17)-8*C17*E17^3)/(D17^2*(D17+6*C17+6*E17)+4*E17^2*(2*E17-3*D17))+N17 -> 33.10441 | P17: =(F17^3*D17 + 2*F17^3*C17 + 2*F17^3*E17)/3 -> 76.666667 | Q17: =((C17^3*D17^2*F17)/12)*((2*D17*F17+3*C17*F17)/(D17*F17+6*F17*C17)) -> 1.0514423e+08 | R17: =2*(K17+G17*N17^2) -> 156708.1 | S17: =((2*F17)^3*D17 + 2*F17^3*(2*C17) + 4*F17^3*E17)/3 -> 393.33333 | T17: =D17^2/4 * (2*R17) -> 1.1282983e+09 | U17: =SQRT(R17/(2*G17)) -> 18.64463
B18: 125S45-08 | C18: 45 | D18: 125 | E18: 101 | F18: 0.8 | G18: 190 | H18: 1.49 | I18: 456000 | J18: =SQRT(I18/G18) -> 48.989795 | K18: 55000 | L18: =SQRT(K18/G18) -> 17.013926 | M18: 62.5 | N18: =( D18 * F18^2 / 2 + 2 * F18 * C18^2 /2 + 2 * F18*E18 *C18)/G18 -> 47.010526 | O18: =(3*C18*D18^2*(C18+2*E18)-8*C18*E18^3)/(D18^2*(D18+6*C18+6*E18)+4*E18^2*(2*E18-3*D18))+N18 -> 64.50242 | P18: =(F18^3*D18 + 2*F18^3*C18 + 2*F18^3*E18)/3 -> 71.168 | Q18: =((C18^3*D18^2*F18)/12)*((2*D18*F18+3*C18*F18)/(D18*F18+6*F18*C18)) -> 92518790 | R18: =2*(K18+G18*N18^2) -> 949796.04 | S18: =((2*F18)^3*D18 + 2*F18^3*(2*C18) + 4*F18^3*E18)/3 -> 270.336 | T18: =D18^2/4 * (2*R18) -> 7.4202816e+09 | U18: =SQRT(R18/(2*G18)) -> 49.994632
B19: 125S45-10 | C19: 45 | D19: 125 | E19: 15 | F19: 1 | G19: 236 | H19: 1.85 | I19: 565000 | J19: =SQRT(I19/G19) -> 48.929212 | K19: 67000 | L19: =SQRT(K19/G19) -> 16.849282 | M19: 62.5 | N19: =( D19 * F19^2 / 2 + 2 * F19 * C19^2 /2 + 2 * F19*E19 *C19)/G19 -> 14.565678 | O19: =(3*C19*D19^2*(C19+2*E19)-8*C19*E19^3)/(D19^2*(D19+6*C19+6*E19)+4*E19^2*(2*E19-3*D19))+N19 -> 36.1667 | P19: =(F19^3*D19 + 2*F19^3*C19 + 2*F19^3*E19)/3 -> 81.666667 | Q19: =((C19^3*D19^2*F19)/12)*((2*D19*F19+3*C19*F19)/(D19*F19+6*F19*C19)) -> 1.1564849e+08 | R19: =2*(K19+G19*N19^2) -> 234139.04 | S19: =((2*F19)^3*D19 + 2*F19^3*(2*C19) + 4*F19^3*E19)/3 -> 413.33333 | T19: =D19^2/4 * (2*R19) -> 1.8292112e+09 | U19: =SQRT(R19/(2*G19)) -> 22.272343
B20: 140S45-08 | C20: 45 | D20: 140 | E20: 15 | F20: 0.8 | G20: 202 | H20: 1.58 | I20: 595000 | J20: =SQRT(I20/G20) -> 54.272871 | K20: 57000 | L20: =SQRT(K20/G20) -> 16.798161 | M20: 70 | N20: =( D20 * F20^2 / 2 + 2 * F20 * C20^2 /2 + 2 * F20*E20 *C20)/G20 -> 13.588119 | O20: =(3*C20*D20^2*(C20+2*E20)-8*C20*E20^3)/(D20^2*(D20+6*C20+6*E20)+4*E20^2*(2*E20-3*D20))+N20 -> 34.461756 | P20: =(F20^3*D20 + 2*F20^3*C20 + 2*F20^3*E20)/3 -> 44.373333 | Q20: =((C20^3*D20^2*F20)/12)*((2*D20*F20+3*C20*F20)/(D20*F20+6*F20*C20)) -> 1.2052207e+08 | R20: =2*(K20+G20*N20^2) -> 188593.34 | S20: =((2*F20)^3*D20 + 2*F20^3*(2*C20) + 4*F20^3*E20)/3 -> 232.10667 | T20: =D20^2/4 * (2*R20) -> 1.8482147e+09 | U20: =SQRT(R20/(2*G20)) -> 21.605906
B21: 140S45-10 | C21: 45 | D21: 140 | E21: 15 | F21: 1 | G21: 251 | H21: 1.97 | I21: 738000 | J21: =SQRT(I21/G21) -> 54.223971 | K21: 70000 | L21: =SQRT(K21/G21) -> 16.699834 | M21: 70 | N21: =( D21 * F21^2 / 2 + 2 * F21 * C21^2 /2 + 2 * F21*E21 *C21)/G21 -> 13.7251 | O21: =(3*C21*D21^2*(C21+2*E21)-8*C21*E21^3)/(D21^2*(D21+6*C21+6*E21)+4*E21^2*(2*E21-3*D21))+N21 -> 34.598737 | P21: =(F21^3*D21 + 2*F21^3*C21 + 2*F21^3*E21)/3 -> 86.666667 | Q21: =((C21^3*D21^2*F21)/12)*((2*D21*F21+3*C21*F21)/(D21*F21+6*F21*C21)) -> 1.5065259e+08 | R21: =2*(K21+G21*N21^2) -> 234565.94 | S21: =((2*F21)^3*D21 + 2*F21^3*(2*C21) + 4*F21^3*E21)/3 -> 453.33333 | T21: =D21^2/4 * (2*R21) -> 2.2987462e+09 | U21: =SQRT(R21/(2*G21)) -> 21.616263
B22: 150S45-08 | C22: 45 | D22: 150 | E22: 15 | F22: 0.8 | G22: 210 | H22: 1.65 | I22: 700000 | J22: =SQRT(I22/G22) -> 57.735027 | K22: 58000 | L22: =SQRT(K22/G22) -> 16.618979 | M22: 75 | N22: =( D22 * F22^2 / 2 + 2 * F22 * C22^2 /2 + 2 * F22*E22 *C22)/G22 -> 13.085714 | O22: =(3*C22*D22^2*(C22+2*E22)-8*C22*E22^3)/(D22^2*(D22+6*C22+6*E22)+4*E22^2*(2*E22-3*D22))+N22 -> 33.505422 | P22: =(F22^3*D22 + 2*F22^3*C22 + 2*F22^3*E22)/3 -> 46.08 | Q22: =((C22^3*D22^2*F22)/12)*((2*D22*F22+3*C22*F22)/(D22*F22+6*F22*C22)) -> 1.415692e+08 | R22: =2*(K22+G22*N22^2) -> 187919.09 | S22: =((2*F22)^3*D22 + 2*F22^3*(2*C22) + 4*F22^3*E22)/3 -> 245.76 | T22: =D22^2/4 * (2*R22) -> 2.1140897e+09 | U22: =SQRT(R22/(2*G22)) -> 21.152456
B23: 150S45-10 | C23: 45 | D23: 150 | E23: 15 | F23: 1 | G23: 261 | H23: 2.05 | I23: 868000 | J23: =SQRT(I23/G23) -> 57.668627 | K23: 71000 | L23: =SQRT(K23/G23) -> 16.493352 | M23: 75 | N23: =( D23 * F23^2 / 2 + 2 * F23 * C23^2 /2 + 2 * F23*E23 *C23)/G23 -> 13.218391 | O23: =(3*C23*D23^2*(C23+2*E23)-8*C23*E23^3)/(D23^2*(D23+6*C23+6*E23)+4*E23^2*(2*E23-3*D23))+N23 -> 33.638099 | P23: =(F23^3*D23 + 2*F23^3*C23 + 2*F23^3*E23)/3 -> 90 | Q23: =((C23^3*D23^2*F23)/12)*((2*D23*F23+3*C23*F23)/(D23*F23+6*F23*C23)) -> 1.769615e+08 | R23: =2*(K23+G23*N23^2) -> 233206.9 | S23: =((2*F23)^3*D23 + 2*F23^3*(2*C23) + 4*F23^3*E23)/3 -> 480 | T23: =D23^2/4 * (2*R23) -> 2.6235776e+09 | U23: =SQRT(R23/(2*G23)) -> 21.136615
B24: 160S45-08 | C24: 45 | D24: 160 | E24: 15 | F24: 0.8 | G24: 210 | H24: 1.65 | I24: 700000 | J24: =SQRT(I24/G24) -> 57.735027 | K24: 58000 | L24: =SQRT(K24/G24) -> 16.618979 | M24: 75 | N24: =( D24 * F24^2 / 2 + 2 * F24 * C24^2 /2 + 2 * F24*E24 *C24)/G24 -> 13.100952 | O24: =(3*C24*D24^2*(C24+2*E24)-8*C24*E24^3)/(D24^2*(D24+6*C24+6*E24)+4*E24^2*(2*E24-3*D24))+N24 -> 33.088943 | P24: =(F24^3*D24 + 2*F24^3*C24 + 2*F24^3*E24)/3 -> 47.786667 | Q24: =((C24^3*D24^2*F24)/12)*((2*D24*F24+3*C24*F24)/(D24*F24+6*F24*C24)) -> 1.6456186e+08 | R24: =2*(K24+G24*N24^2) -> 188086.68 | S24: =((2*F24)^3*D24 + 2*F24^3*(2*C24) + 4*F24^3*E24)/3 -> 259.41333 | T24: =D24^2/4 * (2*R24) -> 2.4075095e+09 | U24: =SQRT(R24/(2*G24)) -> 21.161886
B25: 160S45-10 | C25: 45 | D25: 160 | E25: 15 | F25: 1 | G25: 261 | H25: 2.05 | I25: 868000 | J25: =SQRT(I25/G25) -> 57.668627 | K25: 71000 | L25: =SQRT(K25/G25) -> 16.493352 | M25: 75 | N25: =( D25 * F25^2 / 2 + 2 * F25 * C25^2 /2 + 2 * F25*E25 *C25)/G25 -> 13.237548 | O25: =(3*C25*D25^2*(C25+2*E25)-8*C25*E25^3)/(D25^2*(D25+6*C25+6*E25)+4*E25^2*(2*E25-3*D25))+N25 -> 33.225539 | P25: =(F25^3*D25 + 2*F25^3*C25 + 2*F25^3*E25)/3 -> 93.333333 | Q25: =((C25^3*D25^2*F25)/12)*((2*D25*F25+3*C25*F25)/(D25*F25+6*F25*C25)) -> 2.0570233e+08 | R25: =2*(K25+G25*N25^2) -> 233471.46 | S25: =((2*F25)^3*D25 + 2*F25^3*(2*C25) + 4*F25^3*E25)/3 -> 506.66667 | T25: =D25^2/4 * (2*R25) -> 2.9884346e+09 | U25: =SQRT(R25/(2*G25)) -> 21.148601
A26: MP-STUD | B26: MP-74 | C26: 40 | D26: 74 | F26: 0.6 | G26: 124.45 | H26: =G26*7.82*10^-3 -> 0.973199 | I26: 85757 | J26: =SQRT(I26/G26) -> 26.250485 | K26: 31270 | L26: =SQRT(K26/G26) -> 15.851359 | M26: =D26/2 -> 37
B27: MP-90 | C27: 40 | D27: 90 | F27: 0.6 | G27: 124 | H27: =G27*7.82*10^-3 -> 0.96968 | I27: 183557.8 | J27: =SQRT(I27/G27) -> 38.47473 | K27: 31270 | L27: =SQRT(K27/G27) -> 15.880095 | M27: =D27/2 -> 45
B28: MP-100 | C28: 40 | D28: 100 | F28: 0.6 | G28: 124 | H28: =G28*7.82*10^-3 -> 0.96968 | I28: 183557.8 | J28: =SQRT(I28/G28) -> 38.47473 | K28: 31270 | L28: =SQRT(K28/G28) -> 15.880095 | M28: =D28/2 -> 50
B29: MP-124 | C29: 40 | D29: 124 | F29: 0.6 | G29: 124 | H29: =G29*7.82*10^-3 -> 0.96968 | I29: 311171.2 | J29: =SQRT(I29/G29) -> 50.094363 | K29: 31270 | L29: =SQRT(K29/G29) -> 15.880095 | M29: =D29/2 -> 62
B30: MP-140 | C30: 40 | D30: 150 | F30: 0.6 | G30: 124 | H30: =G30*7.82*10^-3 -> 0.96968 | I30: 489866.2 | J30: =SQRT(I30/G30) -> 62.853273 | K30: 31270 | L30: =SQRT(K30/G30) -> 15.880095 | M30: =D30/2 -> 75
B31: MP-150 | C31: 40 | D31: 150 | F31: 0.6 | G31: 124 | H31: =G31*7.82*10^-3 -> 0.96968 | I31: 489866.2 | J31: =SQRT(I31/G31) -> 62.853273 | K31: 31270 | L31: =SQRT(K31/G31) -> 15.880095 | M31: =D31/2 -> 75
A32: CH-STUD | B32: 64CHS-08 | C32: 35 | D32: 64 | E32: 15 | F32: 0.8 | G32: 168.6 | H32: =7.2*G32*10^-3 -> 1.21392 | I32: 173620 | J32: =SQRT(I32/G32) -> 32.090102 | K32: 26200 | L32: =SQRT(K32/G32) -> 12.465849 | M32: 42.99 | N32: =( D32 * F32^2 / 2 + 2 * F32 * C32^2 /2 + 2 * F32*E32 *C32)/G32 -> 10.916251
B33: 75CHS-08 | C33: 35 | D33: 75 | E33: 15 | F33: 0.8 | G33: 177.4 | H33: =7.2*G33*10^-3 -> 1.27728 | I33: 231600 | J33: =SQRT(I33/G33) -> 36.132039 | K33: 27900 | L33: =SQRT(K33/G33) -> 12.540802 | M33: 47.74 | N33: =( D33 * F33^2 / 2 + 2 * F33 * C33^2 /2 + 2 * F33*E33 *C33)/G33 -> 10.394589
B34: 92CHS-08 | C34: 35 | D34: 92 | E34: 15 | F34: 0.8 | G34: 191 | H34: =7.2*G34*10^-3 -> 1.3752 | I34: 342000 | J34: =SQRT(I34/G34) -> 42.315197 | K34: 30300 | L34: =SQRT(K34/G34) -> 12.595187 | M34: 55.21 | N34: =( D34 * F34^2 / 2 + 2 * F34 * C34^2 /2 + 2 * F34*E34 *C34)/G34 -> 9.6829319
B35: 102CHS-08 | C35: 35 | D35: 102 | E35: 15 | F35: 0.8 | G35: 199 | H35: =7.2*G35*10^-3 -> 1.4328 | I35: 419700 | J35: =SQRT(I35/G35) -> 45.924342 | K35: 31490 | L35: =SQRT(K35/G35) -> 12.579396 | M35: 59.67 | N35: =( D35 * F35^2 / 2 + 2 * F35 * C35^2 /2 + 2 * F35*E35 *C35)/G35 -> 9.3097487
B36: 127CHS-08 | C36: 35 | D36: 127 | E36: 15 | F36: 0.8 | G36: 237 | H36: =7.2*G36*10^-3 -> 1.7064 | I36: 519361 | J36: =SQRT(I36/G36) -> 46.812355 | K36: 30230 | L36: =SQRT(K36/G36) -> 11.293925 | M36: 60.38 | N36: =( D36 * F36^2 / 2 + 2 * F36 * C36^2 /2 + 2 * F36*E36 *C36)/G36 -> 7.8508017
B37: 152CHS-08 | C37: 35 | D37: 152 | E37: 15 | F37: 0.8 | G37: 239 | H37: =7.2*G37*10^-3 -> 1.7208 | I37: 963600 | J37: =SQRT(I37/G37) -> 63.49645 | K37: 36410 | L37: =SQRT(K37/G37) -> 12.342735 | M37: 82.52 | N37: =( D37 * F37^2 / 2 + 2 * F37 * C37^2 /2 + 2 * F37*E37 *C37)/G37 -> 7.8185774
A38: T.Silent | B38: 19TH-A-74x45x10x0.5 | C38: 40 | D38: 74 | F38: 0.6 | G38: 113.323 | H38: =G38*7.82*10^-3 -> 0.88618586 | I38: 42132 | J38: =SQRT(I38/G38) -> 19.281775 | K38: 21343 | L38: =SQRT(K38/G38) -> 13.723621 | M38: 51.4 | Q38: =((C38^3*D38^2*F38)/12)*((2*D38*F38+3*C38*F38)/(D38*F38+6*F38*C38)) -> 14956107
B39: 19TH-A-90x45x10x0.5 | C39: 40 | D39: 90 | F39: 0.6 | G39: 128.323 | H39: =G39*7.82*10^-3 -> 1.0034859 | I39: 103939 | J39: =SQRT(I39/G39) -> 28.460139 | K39: 24024 | L39: =SQRT(K39/G39) -> 13.682656
B40: 19TH-A-100x45x10x0.5 | C40: 40 | D40: 100 | F40: 0.6 | G40: 143.323 | H40: =G40*7.82*10^-3 -> 1.1207859 | I40: 199799 | J40: =SQRT(I40/G40) -> 37.336939 | K40: 26144 | L40: =SQRT(K40/G40) -> 13.506041
...

Sheet Type
B2: C-STUD | C2: 기본
B3: C-STUD | C3: 겹침
B4: C-STUD | C4: 맞댐이음
B5: C-STUD | C5: 이중스터드
B6: CH-STUD
B7: SH-STUD
B8: R.STUD
B9: T.silent-STUD
B10: MP-STUD
B11: MP-STUD(V-brace)
B12: AC-STUD
B13: SQ-STUD
B14: HR-STUD

Sheet 단면성능
A1: 경량 스틸 스터드 단면 성능표
A2: DXF 파일에서 폴리라인 단면을 추출하여 자동 계산 (단위: mm, mm², mm³, mm⁴)
A4: 그룹 | B4: 단면명 | C4: 치수 | F4: 단면적 | G4: 도심 | I4: 단면2차모멘트 | K4: 단면계수 | M4: 회전반경
C5: H (mm) | D5: B (mm) | E5: t (mm) | G5: cx (mm) | H5: cy (mm) | I5: Ix (mm⁴) | J5: Iy (mm⁴) | K5: Sx (mm³) | L5: Sy (mm³) | M5: rx (mm) | N5: ry (mm) | O5: 그룹분류
A6: HR-STUD | B6: HR-124 | C6: 124 | D6: 45 | F6: 205.03 | G6: 16.13 | H6: 62 | I6: 449540 | J6: 44008 | K6: 7251 | L6: 1524 | M6: 46.82 | N6: 14.65 | O6: HR-STUD
B7: HR-150 | C7: 150 | D7: 45 | F7: 225.83 | G7: 14.68 | H7: 75 | I7: 695982 | J7: 48691 | K7: 9280 | L7: 1606 | M7: 55.51 | N7: 14.68 | O7: HR-STUD
B8: HR-174 | C8: 174 | D8: 45 | F8: 245.03 | G8: 13.56 | H8: 87 | I8: 984977 | J8: 52328 | K8: 11322 | L8: 1664 | M8: 63.4 | N8: 14.61 | O8: HR-STUD
B9: HR-200 | C9: 200 | D9: 45 | F9: 265.83 | G9: 12.53 | H9: 100 | I9: 1371260 | J9: 55632 | K9: 13713 | L9: 1713 | M9: 71.82 | N9: 14.47 | O9: HR-STUD
A10: T.silent-STUD | B10: 19TH-A-74x45x10x0.5 | C10: 74.5 | D10: 45.5 | E10: 0.5 | F10: 257.61 | G10: 30.24 | H10: 37 | I10: 200922 | J10: 45552 | K10: 5394 | L10: 1494 | M10: 27.93 | N10: 13.3 | O10: T.silent-STUD
B11: 19TH-A-90x45x10x0.5 | C11: 90.5 | D11: 45.5 | E11: 0.5 | F11: 273.61 | G11: 31.08 | H11: 45.58 | I11: 310833 | J11: 48704 | K11: 6782 | L11: 1554 | M11: 33.71 | N11: 13.34 | O11: T.silent-STUD
B12: 19TH-A-100x45x10x0.5 | C12: 100.5 | D12: 45.5 | E12: 0.5 | F12: 283.61 | G12: 31.56 | H12: 50.56 | I12: 391180 | J12: 50494 | K12: 7698 | L12: 1587 | M12: 37.14 | N12: 13.34 | O12: T.silent-STUD
B13: 19TH-A-124x45x10x0.5 | C13: 120.5 | D13: 45.5 | E13: 0.5 | F13: 303.61 | G13: 32.43 | H13: 60.53 | I13: 585561 | J13: 53720 | K13: 9635 | L13: 1644 | M13: 43.92 | N13: 13.3 | O13: T.silent-STUD
B14: 19TH-A-140x45x10x0.5 | C14: 140.5 | D14: 45.5 | E14: 0.5 | F14: 323.61 | G14: 33.19 | H14: 69.94 | I14: 827986 | J14: 56547 | K14: 11777 | L14: 1691 | M14: 50.58 | N14: 13.22 | O14: T.silent-STUD
B15: 19TH-A-150x45x10x0.5 | C15: 150.5 | D15: 45.5 | E15: 0.5 | F15: 333.61 | G15: 33.53 | H15: 74.94 | I15: 968641 | J15: 57834 | K15: 12863 | L15: 1712 | M15: 53.88 | N15: 13.17 | O15: T.silent-STUD
A16: CH-STUD | B16: 64CHS-08 | C16: 65 | D16: 35 | E16: 0.8 | F16: 139.84 | G16: 20.45 | H16: 32.46 | I16: 80289 | J16: 17796 | K16: 2468 | L16: 870 | M16: 23.96 | N16: 11.28 | O16: CH-STUD
B17: 75CHS-08 | C17: 76 | D17: 35 | E17: 0.8 | F17: 148.64 | G17: 21.29 | H17: 37.17 | I17: 116736 | J17: 19451 | K17: 3006 | L17: 914 | M17: 28.02 | N17: 11.44 | O17: CH-STUD
B18: 92CHS-08 | C18: 93 | D18: 35 | E18: 0.8 | F18: 162.24 | G18: 22.4 | H18: 44.61 | I18: 190620 | J18: 21650 | K18: 3939 | L18: 966 | M18: 34.28 | N18: 11.55 | O18: CH-STUD
B19: 102CHS-08 | C19: 103 | D19: 35 | E19: 0.8 | F19: 170.24 | G19: 22.98 | H19: 49.06 | I19: 244765 | J19: 22795 | K19: 4538 | L19: 992 | M19: 37.92 | N19: 11.57 | O19: CH-STUD
B20: 127CHS-08 | C20: 128 | D20: 35 | E20: 0.8 | F20: 190.24 | G20: 24.2 | H20: 60.4 | I20: 417851 | J20: 25213 | K20: 6181 | L20: 1042 | M20: 46.87 | N20: 11.51 | O20: CH-STUD
B21: 152CHS-08 | C21: 153 | D21: 35 | E21: 0.8 | F21: 210.24 | G21: 25.19 | H21: 71.96 | I21: 649969 | J21: 27167 | K21: 8020 | L21: 1079 | M21: 55.6 | N21: 11.37 | O21: CH-STUD
A22: CH-STUD(개량형) | B22: 64CHS-08 | C22: 65 | D22: 35 | E22: 0.8 | F22: 139.84 | G22: 21.69 | H22: 29.98 | I22: 88053 | J22: 19526 | K22: 2514 | L22: 900 | M22: 25.09 | N22: 11.82 | O22: CH-STUD(개량형)
B23: 75CHS-08 | C23: 76 | D23: 35 | E23: 0.8 | F23: 148.64 | G23: 22.46 | H23: 34.83 | I23: 127819 | J23: 20898 | K23: 3105 | L23: 931 | M23: 29.32 | N23: 11.86 | O23: CH-STUD(개량형)
B24: 92CHS-08 | C24: 93 | D24: 35 | E24: 0.8 | F24: 162.24 | G24: 23.48 | H24: 42.46 | I24: 206944 | J24: 22735 | K24: 4095 | L24: 968 | M24: 35.71 | N24: 11.84 | O24: CH-STUD(개량형)
B25: 102CHS-08 | C25: 103 | D25: 35 | E25: 0.8 | F25: 170.24 | G25: 24 | H25: 47.02 | I25: 264214 | J25: 23678 | K25: 4720 | L25: 987 | M25: 39.4 | N25: 11.79 | O25: CH-STUD(개량형)
B26: 127CHS-08 | C26: 128 | D26: 35 | E26: 0.8 | F26: 190.24 | G26: 25.11 | H26: 58.57 | I26: 445259 | J26: 25704 | K26: 6413 | L26: 1023 | M26: 48.38 | N26: 11.62 | O26: CH-STUD(개량형)
B27: 152CHS-08 | C27: 153 | D27: 35 | E27: 0.8 | F27: 210.24 | G27: 26.02 | H27: 70.3 | I27: 685468 | J27: 27325 | K27: 8289 | L27: 1050 | M27: 57.1 | N27: 11.4 | O27: CH-STUD(개량형)
A28: I-STUD | B28: I-STUD 75-06 | C28: 75 | D28: 40 | E28: 0.6 | F28: 119.52 | G28: 21.45 | H28: 37.5 | I28: 123019 | J28: 10605 | K28: 3281 | L28: 494 | M28: 32.08 | N28: 9.42 | O28: I-STUD
B29: I-STUD 102-06 | C29: 102 | D29: 40 | E29: 0.6 | F29: 135.72 | G29: 21.28 | H29: 51 | I29: 242970 | J29: 10621 | K29: 4764 | L29: 499 | M29: 42.31 | N29: 8.85 | O29: I-STUD
B30: I-STUD 75-08 | C30: 75 | D30: 40 | E30: 0.8 | F30: 158.88 | G30: 21.45 | H30: 37.5 | I30: 162113 | J30: 14138 | K30: 4323 | L30: 659 | M30: 31.94 | N30: 9.43 | O30: I-STUD
B31: I-STUD 92-08 | C31: 92 | D31: 40 | E31: 0.8 | F31: 172.48 | G31: 21.34 | H31: 46 | I31: 254892 | J31: 14071 | K31: 5541 | L31: 659 | M31: 38.44 | N31: 9.03 | O31: I-STUD
B32: I-STUD 102-08 | C32: 102 | D32: 40 | E32: 0.8 | F32: 180.48 | G32: 21.28 | H32: 51 | I32: 321011 | J32: 14135 | K32: 6294 | L32: 664 | M32: 42.17 | N32: 8.85 | O32: I-STUD
B33: I-STUD 127-08 | C33: 127 | D33: 40 | E33: 0.8 | F33: 200.48 | G33: 21.15 | H33: 63.5 | I33: 526639 | J33: 14190 | K33: 8294 | L33: 671 | M33: 51.25 | N33: 8.41 | O33: I-STUD
B34: I-STUD 152-08 | C34: 152 | D34: 40 | E34: 0.8 | F34: 220.48 | G34: 21.05 | H34: 76 | I34: 794911 | J34: 14216 | K34: 10459 | L34: 675 | M34: 60.04 | N34: 8.03 | O34: I-STUD
A35: MP-STUD | B35: MP-74 | C35: 74 | D35: 40 | F35: 167.62 | G35: 20 | H35: 37 | I35: 115476 | J35: 41688 | K35: 3121 | L35: 2084 | M35: 26.25 | N35: 15.77 | O35: MP-STUD
B36: MP-90 | C36: 90 | D36: 40 | F36: 167.62 | G36: 20 | H36: 45 | I36: 189901 | J36: 41643 | K36: 4220 | L36: 2082 | M36: 33.66 | N36: 15.76 | O36: MP-STUD
B37: MP-100 | C37: 100 | D37: 40 | F37: 167.62 | G37: 20 | H37: 50 | I37: 247351 | J37: 41756 | K37: 4947 | L37: 2088 | M37: 38.41 | N37: 15.78 | O37: MP-STUD
B38: MP-124 | C38: 125 | D38: 40 | F38: 167.62 | G38: 20 | H38: 62.5 | I38: 427551 | J38: 41711 | K38: 6841 | L38: 2086 | M38: 50.5 | N38: 15.77 | O38: MP-STUD
B39: MP-140 | C39: 141 | D39: 40 | F39: 167.62 | G39: 20 | H39: 70.5 | I39: 570407 | J39: 41824 | K39: 8091 | L39: 2091 | M39: 58.34 | N39: 15.8 | O39: MP-STUD
B40: MP-150 | C40: 151 | D40: 40 | F40: 167.62 | G40: 20 | H40: 75.5 | I40: 670543 | J40: 41733 | K40: 8881 | L40: 2087 | M40: 63.25 | N40: 15.78 | O40: MP-STUD
A41: RV-STUD | B41: RV-74 | C41: 74 | D41: 40 | F41: 138.3 | G41: 12.94 | H41: 39.42 | I41: 96715 | J41: 21609 | K41: 2454 | L41: 799 | M41: 26.44 | N41: 12.5 | O41: RV-STUD
...
